Workbook
Name \: #REF!
Name \\: #REF!
Name \хз: #REF!
Name _1: #REF!
Name Excel_BuiltIn_Print_Area_1_1: #REF!
Name Excel_BuiltIn_Print_Area_20_1: #REF!
Name Excel_BuiltIn_Print_Area_4: #REF!
Name Excel_BuiltIn_Print_Area_5: #REF!
Name H: #REF!
Name kjhiu: #REF!
Name smet: #REF!
Name tlbLists: #REF!
Name TR10B: #REF!
Name TR10C: #REF!
Name TR10EXP: #REF!
Name TR10PSZ: #REF!
Name TR10S: #REF!
Name TR10ST: #REF!
Name TR10Y: #REF!
Name TR111S: #REF!
Name TR11B: #REF!
Name TR11PSZ: #REF!
Name TR11S: #REF!
Name TR11ST: #REF!
Name TR11Y: #REF!
Name TR12B: #REF!
Name TR12EXP: #REF!
Name TR12PSZ: #REF!
Name TR12S: #REF!
Name TR12ST: #REF!
Name TR12Y: #REF!
Name TR15B: #REF!
Name TR15EXP: #REF!
Name TR15PSZ: #REF!
Name TR15S: #REF!
Name TR15ST: #REF!
Name TR15Y: #REF!
Name TR1EXP: #REF!
Name TR20B: #REF!
Name TR20EXP: #REF!
Name TR20PSZ: #REF!
Name TR20S: #REF!
Name TR20ST: #REF!
Name TR20Y: #REF!
Name TR21Y: #REF!
Name TR23B: #REF!
Name TR23EXP: #REF!
Name TR23PSZ: #REF!
Name TR23S: #REF!
Name TR23ST: #REF!
Name TR23Y: #REF!
Name TR8B: #REF!
Name TR8EXP: #REF!
Name TR8PSZ: #REF!
Name TR8S: #REF!
Name TR8ST: #REF!
Name TR8Y: #REF!
Name TR9B: #REF!
Name TR9EXP: #REF!
Name TR9PSZ: #REF!

Sheet Прил. № 5 Ф1(1д) прот
M1: Приложение № 5 к приказу ФАС России от 16.12.2022 № 995/22
O3: Форма № 1 (1д)
A5: Протокол (Согласование) цены (прогнозной цены) единицы продукции и выбора вида цены
K7: Государственный заказчик / Заказчик:
K8: Процедура: | L8: Определение цены контракта
K10: Метод определения цены: | L10: Затратный
K11: Примечание:
A14: № п/п | B14: Полное наименование товара, работы, услуги, шифр | C14: Код ОКП/ ОКПД2 | D14: Код ЕКПС (при наличии) | E14: ФНН (при наличии) | F14: Единица измерения | G14: Техническая документация (ТУ, ТЗ, КД, ГОСТ, иное), орган и дата утверждения | H14: Календарный год или срок действия цены | J14: Цена, заявленная организацией- поставщиком (подрядчиком, исполнителем) (без НДС, руб.) | K14: Цена, предлагаемая отраслевым органом (без НДС, руб.) | L14: Цена, принятая государственным заказчиком / заказчиком (без НДС, руб.) | M14: Вид цены
H15: начало | I15: окончание | M15: Предложено организацией-поставщиком (подрядчиком, исполнителем) | N15: Предложено отраслевым органом | O15: Предложено государственным заказчиком / заказчиком
A16: 1 | B16: 2 | C16: 3 | D16: 4 | E16: 5 | F16: 6 | G16: 7 | H16: 8.1 | I16: 8.2 | J16: 9 | K16: 10 | L16: 11 | M16: 12 | N16: 13 | O16: 14
A17: 1 | B17: ТЕМА | C17: 72.19.29 | D17: - | E17: - | F17: СЧ ОКР | G17: Техническое задание № | H17: Дата подписания договора | I17: 01.03.2026 | J17: ='2д план кальк (2)'!K58 | K17: - | L17: - | M17: ориентировочная | N17: - | O17: -
K19: Начальник ОФЭиАУ НИОКР
B20: _____________________ _____________ | K20: _____________________ Н.О. Васецкая
B21: (подпись) (Ф.И.О.) | K21: (подпись) (Ф.И.О.)
B22: «____» __________________ 2026 г. | K22: «____» __________________ 2026 г.
B23: М.П.
K25: Проректор по научной работе
K26: _____________________ Ю.В. Фомин
K27: (подпись) (Ф.И.О.)
K28: «____» __________________ 2026 г.
K29: М.П.

Sheet 2д план кальк (2)
M1: Форма № 2д
A3: Плановая калькуляция затрат
A4: на 2026-2027 гг.
B6: Наименование товара, работы, услуги | D6: ТЕМА
B7: Код по ОКП/ОКПД2 (шифр)
B8: Код по ЕКПС (при наличии)
B9: ФНН (при наличии)
B10: Калькуляционная единица | D10: этап
D11: (штука, комплект, этап, единица работы (услуги), иное)
B12: Техническая документация | D12: Техническое задание №
D13: (ТУ, ТЗ, КД, ГОСТ, иное) орган и дата утверждения
M14: (руб.)
A15: № № строк | B15: Наименование статей калькуляции | C15: Стоимостная оценка затрат на производство в условиях первого года производства | E15: Затраты на производство в первом году производства | F15: Принято государствен-ным заказчиком / заказчиком | G15: 2027-ый год | K15: Предложено организацией-поставщиком (подрядчиком, исполнителем) | L15: Принято государствен-ным заказчиком / заказчиком | M15: Примечание
G16: стоимостная оценка затрат 2027-ого года в условиях первого года производства | H16: применяе-мый индекс цен | I16: затраты 2027-го года | J16: принято государствен-ным заказчиком / заказчиком
A19: 1 | B19: 2 | C19: 3 | E19: 4 | F19: 5 | G19: 6 | H19: 7 | I19: 8 | J19: 9 | K19: 10 | L19: 11 | M19: 12
A20: 0100 | B20: Материальные затраты - всего: | C20: 0 | E20: 0 | G20: 0 | H20: - | I20: 0 | K20: =I20+E20
B21: в том числе:
A22: 0101 | B22: приобретение сырья, материалов и вспомогательных материалов | C22: 0 | E22: 0 | G22: 0 | H22: - | I22: 0 | K22: =I22+E22
A23: 0102 | B23: приобретение полуфабрикатов | C23: 0 | E23: 0 | G23: 0 | H23: - | I23: 0 | K23: =I23+E23
A24: 0103 | B24: возвратные отходы | C24: 0 | E24: 0 | G24: 0 | H24: - | I24: 0 | K24: =I24+E24
A25: 0104 | B25: приобретение комплектующих изделий | C25: 0 | E25: 0 | G25: 0 | H25: - | I25: 0 | K25: =I25+E25
A26: 0105 | B26: оплата работ и услуг сторонних организаций производственного характера | C26: 0 | E26: 0 | G26: 0 | H26: - | I26: 0 | K26: =I26+E26
A27: 0106 | B27: транспортно-заготовительные затраты | C27: 0 | E27: 0 | G27: 0 | H27: - | I27: 0 | K27: =I27+E27
A28: 0107 | B28: топливо на технологические цели | C28: 0 | E28: 0 | G28: 0 | H28: - | I28: 0 | K28: =I28+E28
A29: 0108 | B29: энергия на технологические цели | C29: 0 | E29: 0 | G29: 0 | H29: - | I29: 0 | K29: =I29+E29
A30: 0109 | B30: тара и упаковка | C30: 0 | E30: 0 | G30: 0 | H30: - | I30: 0 | K30: =I30+E30
A31: 0110 | B31: затраты на изделия собственного производства | C31: 0 | E31: 0 | G31: 0 | H31: - | I31: 0 | K31: =I31+E31
A32: 0200 | B32: Затраты на оплату труда - всего: | C32: =C34+C35 | E32: =E34+E35 | G32: =G34+G35 | H32: - | I32: =I34+I35 | K32: =I32+E32
B33: в том числе:
A34: 0201 | B34: основная заработная плата | C34: =ROUND('22 (22д) свед. о норм_26'!D15*C59,2) | E34: ='9 (9д) ОЗП НИР(ОКР)'!H13 | G34: =ROUND('22 (22д) свед. о норм_26'!D15*G59,2) | H34: - | I34: ='9 (9д) ОЗП НИР(ОКР)'!H18 | K34: =I34+E34
A35: 0202 | B35: дополнительная заработная плата | C35: =ROUND(C34*0.086866,2) | E35: =ROUND(E34*0.086866,2) | G35: =ROUND(G34*0.086866,2) | H35: - | I35: =ROUND(I34*0.086866,2) | K35: =I35+E35
A36: 0300 | B36: Страховые взносы на обязательное социальное страхование | C36: =ROUND(C32*0.302,2) | E36: =ROUND(E32*0.302,2) | G36: =ROUND(G32*0.302,2) | H36: - | I36: =ROUND(I32*0.302,2) | K36: =I36+E36
A37: 0400 | B37: Затраты на подготовку и освоение производства - всего: | C37: 0 | E37: 0 | G37: 0 | H37: - | I37: 0 | K37: =I37+E37
B38: в том числе:
A39: 0401 | B39: пусковые затраты | C39: 0 | E39: 0 | G39: 0 | H39: - | I39: 0 | K39: =I39+E39
A40: 0402 | B40: затраты на подготовку и освоение новых видов продукции | C40: 0 | E40: 0 | G40: 0 | H40: - | I40: 0 | K40: =I40+E40
A41: 0500 | B41: Затраты на специальную технологическую оснастку | C41: 0 | E41: 0 | G41: 0 | I41: 0 | K41: =I41+E41
A42: 0600 | B42: Затраты на специальное оборудование для научных (экспериментальных) работ9 | C42: 0 | E42: 0 | G42: 0 | H42: - | I42: 0 | K42: =I42+E42
A43: 0700 | B43: Специальные затраты | C43: 0 | E43: 0 | G43: 0 | H43: - | I43: 0 | K43: =I43+E43
A44: 0800 | B44: Общепроизводственные затраты | C44: 0 | E44: 0 | G44: 0 | H44: - | I44: 0 | K44: =I44+E44
...

Sheet Ф.2а(2ад)
IB1: Форма № 2А (2Ад)
A3: Плановая калькуляция затрат на продукцию и отчетная калькуляция затрат на аналог
CZ4: на | DF4: 2026-2027 | DX4: гг.
G6: Наименование, шифр товара, работы (услуги), | BK6: ТЕМА
G7: № этапа | BK7: 1
G8: Код по ОКП/ОКПД2 (шифр)
G9: Код по ЕКПС (при наличии)
G10: ФНН (при наличии)
G11: Калькуляционная единица | BK11: этап
BK12: (штука, комплект, этап, единица работы (услуги), иное)
G13: Техническая документация | BK13: Техническое задание №
BK14: (ТУ, ТЗ, КД, ГОСТ, иное) орган и дата утверждения
IB15: Таблица 1
A16: № № строк | G16: Наименование статьи затрат | BK16: Данные по фактическим затратам по аналогу | FF16: Планируемые затраты на продукцию
BK17: наименование материала, работы (услуги) - аналога | CC17: наименование государственного заказчика (заказчика) аналога | CU17: №, дата договора (контракта) на изготовление аналога, № этапа | DK17: наименование поставщика (исполнителя, изготовителя) аналога | EC17: сроки поставки/ выполнения/ изготовления аналога | ET17: затраты по аналогу (руб.) | FF17: коэффициент сопостави-мости_ | FS17: итого приведенные затраты (гр. 3.6 * гр. 4) | GH17: применяемый индекс цен | GX17: предложено организацией-поставщиком (подрядчиком, исполнителем) (руб.) | HM17: принято государственным заказчиком/ заказчиком
A18: 1 | G18: 2 | BK18: 3.1 | CC18: 3.2 | CU18: 3.3 | DK18: 3.4 | EC18: 3.5 | ET18: 3.6 | FF18: 4 | FS18: 5 | GH18: 6 | GX18: 7 | HM18: 8
A19: 0100 | G19: Материальные затраты - всего:
G20: в том числе:
A21: 0101 | G21: приобретение сырья, материалов и вспомогательных материалов
A22: 0102 | G22: приобретение полуфабрикатов
A23: 0103 | G23: возвратные отходы | BK23: Х | CC23: Х | CU23: Х | DK23: Х | EC23: Х | ET23: Х | FF23: Х | FS23: Х | GH23: Х
A24: 0104 | G24: приобретение комплектующих изделий
A25: 0105 | G25: оплата работ и услуг сторонних организаций производственного характера
A26: 0106 | G26: транспортно-заготовительные затраты | BK26: Х | CC26: Х | CU26: Х | DK26: Х | EC26: Х | ET26: Х | FF26: Х | FS26: Х | GH26: Х
A27: 0107 | G27: топливо на технологические цели
A28: 0108 | G28: энергия на технологические цели
A29: 0109 | G29: тара и упаковка
A30: 0110 | G30: затраты на изделия собственного производства
A31: 0200 | G31: Затраты на оплату труда - всего: | BK31: Х | CC31: Х | CU31: Х | DK31: Х | EC31: Х | ET31: Х | FF31: Х | FS31: Х | GH31: Х
G32: в том числе:
A33: 0201 | G33: основная заработная плата
A34: 0202 | G34: дополнительная заработная плата | BK34: Х | CC34: Х | CU34: Х | DK34: Х | EC34: Х | ET34: Х | FF34: Х | FS34: Х | GH34: Х
A35: 0300 | G35: Страховые взносы на обязательное социальное страхование | BK35: Х | CC35: Х | CU35: Х | DK35: Х | EC35: Х | ET35: Х | FF35: Х | FS35: Х | GH35: Х
A36: 0400 | G36: Затраты на подготовку и освоение производства - всего:
G37: в том числе:
A38: 0401 | G38: пусковые затраты
A39: 0402 | G39: затраты на подготовку и освоение новых видов продукции
A40: 0500 | G40: Затраты на специальную технологическую оснастку
A41: 0600 | G41: Затраты на специальное оборудование для научных (экспериментальных) работ
A42: 0700 | G42: Специальные затраты
...

Sheet 9 (9д) ОЗП НИР(ОКР)
K1: Форма № 9 (9д) НИР (ОКР)
A3: РАСШИФРОВКА
B4: основной заработной платы на | C4: НИР «Радар-26», шифр C_GOZ-26, договор № ГОЗ-0412/26
C5: (НИР, ОКР, ее наименование, шифр или код)
A8: № п/п | B8: Наименование этапа, состав работ по этапу | C8: Срок выполнения этапа | D8: Количество привлекаемых специалистов | E8: Квалификационная группа основных работников, привлекаемых к выполнению этапа | F8: Трудоемкость и заработная плата, учтенные при расчете цены | N8: Примечание
F9: трудоемкость выполнения работ (чел./мес.) | G9: стоимость чел./мес. (руб.) | H9: основная заработная плата (гр.6*гр.7) | I9: в том числе доплаты и надбавки, предусмотренные законодательством Российской Федерации, относимые к основной заработной плате
I10: начисления стимулирующего характера5 | J10: начисления, обусловленные районным регулированием | K10: начисления за работу в условиях, отклоняющихся от нормальных | L10: специальные надбавки при выполнении работ, оказании услуг в командировках на территорию иностранных государств, необходимость которых определена требованиями государственного заказчика (заказчика)
A11: 1 | B11: 2 | C11: 3 | D11: 4 | E11: 5 | F11: 6 | G11: 7 | H11: 8 | I11: 9 | J11: 10 | K11: 11 | L11: 12 | N11: 13
A12: 1. | B12: ТЕМА | C12: Дата заключения договора - 01.03.2026 | D12: 5 | E12: Х | F12: 36 | G12: Х | H12: 3624000 | I12: - | J12: - | K12: - | L12: - | N12: -
B13: 2026 год, в т.ч. | C13: 01.03.2026 - 31.12.2026 | D13: 5 | E13: Научные и инженерно-технические работники, всего | F13: 36 | G13: 100666.67 | H13: 3624000 | I13: - | J13: - | K13: - | L13: - | N13: -
E14: в том числе: | I14: - | J14: - | K14: - | L14: - | N14: -
D15: 1 | E15: Старший научный сотрудник | F15: 8 | G15: 118000 | H15: 944000 | I15: - | J15: - | K15: - | L15: - | N15: -
D16: 1 | E16: Ведущий инженер | F16: 8 | G16: 110000 | H16: 880000 | I16: - | J16: - | K16: - | L16: - | N16: -
D17: 3 | E17: Инженер | F17: 20 | G17: 90000 | H17: 1800000 | I17: - | J17: - | K17: - | L17: - | N17: -
B18: 2027 год, в т.ч. | D18: =SUM(D20:D22) | E18: Научные и инженерно-технические работники, всего | F18: =SUM(F20:F22) | G18: ='22 (22д) свед. о норм_27'!D15 | H18: =ROUND(F18*G18,2) | I18: - | J18: - | K18: - | L18: - | N18: -
E19: в том числе: | I19: - | J19: - | K19: - | L19: - | N19: -
E20: Старший научный сотрудник | G20: =$G$18 | H20: =ROUND(F20*G20,2) | I20: - | J20: - | K20: - | L20: - | N20: -
E21: Ведущий инженер | G21: =$G$18 | H21: =ROUND(F21*G21,2) | I21: - | J21: - | K21: - | L21: - | N21: -
E22: Инженер | G22: =$G$18 | H22: =ROUND(F22*G22,2) | I22: - | J22: - | K22: - | L22: - | N22: -
A23: ИТОГО: | D23: =D12 | E23: Х | F23: =F12 | G23: =G12 | H23: =H12 | I23: - | J23: - | K23: - | L23: - | N23: -
B25: Начальник ОФЭиАУ НИОКР | G25: Руководитель договора
B26: _____________________ Н.О. Васецкая | G26: _____________________ А.И. Боровков
B27: (подпись) (Ф.И.О.) | G27: (подпись) (Ф.И.О.)
B28: «____» __________________ 2026 г. | G28: «____» __________________ 2026 г.
G30: Ответственный исполнитель
G31: _____________________ И.Б. Войнов
G32: (подпись) (Ф.И.О.)
G33: «____» __________________ 2026 г.
A35: 1 Информация заполняется по каждому этапу (подэтапу), в отношении которого формируется стоимостной показатель. В случае если технологический цикл производства продукции составляет более 1 года либо год начала производства продукции не соответствует году окончания ее производства и поставки (или завершения отдельных этапов поставки продукции, если государственным контрактом (контрактом) предусмотрены такие этапы), то организация представляет сведения по годам.
A36: 2 К основным работникам относятся основные производственные рабочие, инженерно-технические и другие категории работников, непосредственно участвующие в процессе производства продукции, согласно порядку определения состава затрат, включаемых в цену продукции, поставляемой в рамках государственного оборонного заказа, утвержденному в соответствии с постановлением Правительства Российской Федерации от 2 декабря 2017 года № 1465 "О государственном регулировании цен на продукцию, поставляемую по государственному оборонному заказу, а также о внесении изменений и признании утратившими силу некоторых актов Правительства Российской Федерации".
A37: 3 В случае проведения процедуры перевода в фиксированную цену других видов цен на продукцию организацией с учетом установленных в государственном контракте (контракте) условий уточнения и порядка перевода соответствующего вида цены на продукцию в фиксированную цену графы 6-13 заполняются для отражения затрат по состоянию на конкретную дату. Планируемые затраты до окончания поставки продукции в рамках выполнения государственного контракта (контракта) (или завершения отдельных этапов поставки продукции, если государственным контрактом (контрактом) предусмотрены такие этапы) необходимо заполнить в соответствии с графами 6-13, дополнив форму графами после граф, в которых представлены затраты по состоянию на конкретную дату, аналогичными по содержанию графам 6-13 (с последующей корректировкой нумерации граф) для указания планируемых затрат. В случае если технологический цикл производства продукции составляет более 1 года либо год начала производства продукции не соответствует году окончания ее производства и поставки (или завершения отдельных этапов поставки продукции, если государственным контрактом (контрактом) предусмотрены такие этапы), то организация представляет сведения о затратах по состоянию на конкретную дату в соответствии с графами 6-13 по годам, дополнив форму после графы 13 графами, аналогичными по содержанию графам 6-13 (с последующей корректировкой нумерации граф), на каждый год производства продукции для указания информации.
A38: 4 Указывается используемая единица измерения трудоемкости: нормо-час / человеко-час / человеко-день / человеко-месяц.
A39: 5 Указываются виды начислений стимулирующего характера, порядок и размеры которых определяются коллективным договором или локальным нормативным актом. Организацией представляется соответствующая выписка из документа, в котором определены указанные начисления.
A41: Используемые сокращения и их расшифровка:
A42: НИР (ОКР) – научно-исследовательская работа (опытно-конструкторская работа).

Sheet 20 (20д) приб (26г.)
A1: Форма № 20 (20д)
A3: Расчет и обоснование прибыли
A4: на 2026 г. по ТЕМА
A5: (наименование, шифр товара, работы, услуги)
G7: Таблица 1
A8: №№ строки | B8: Наименование статей затрат | C8: Затраты (руб.) | E8: Рентабельность (%) | G8: Величина прибыли (руб.)
C9: Собственные | D9: Привнесенные | E9: Собственные | F9: Привнесенные
A10: 1 | B10: 2 | C10: 3 | D10: 4 | E10: 5 | F10: 6 | G10: 7
A11: 0100 | B11: Материальные затраты - всего: | C11: Х | D11: - | E11: Х | F11: - | G11: -
B12: в том числе:
A13: 0101 | B13: приобретение сырья, материалов и вспомогательных материалов | C13: Х | D13: - | E13: Х | F13: - | G13: -
A14: 0102 | B14: приобретение полуфабрикатов | C14: Х | D14: - | E14: Х | F14: - | G14: -
A15: 0103 | B15: возвратные отходы | C15: - | D15: - | E15: - | F15: - | G15: -
A16: 0104 | B16: приобретение комплектующих изделий | C16: Х | D16: - | E16: Х | F16: - | G16: -
A17: 0105 | B17: оплата работ и услуг сторонних организаций производственного характера | C17: Х | D17: - | E17: Х | F17: - | G17: -
A18: 0106 | B18: транспортно-заготовительные затраты | C18: - | D18: - | E18: - | F18: - | G18: -
A19: 0107 | B19: топливо на технологические цели | C19: - | D19: - | E19: - | F19: - | G19: -
A20: 0108 | B20: энергия на технологические цели | C20: - | D20: - | E20: - | F20: - | G20: -
A21: 0109 | B21: тара и упаковка | C21: - | D21: - | E21: - | F21: - | G21: -
A22: 0110 | B22: затраты на изделия собственного производства | C22: - | D22: - | E22: - | F22: - | G22: -
A23: 0200 | B23: Затраты на оплату труда - всего: | C23: =C25+C26 | D23: Х | E23: 0 | F23: Х | G23: =G25+G26
B24: в том числе:
A25: 0201 | B25: основная заработная плата | C25: ='2д план кальк (2)'!E34 | D25: Х | E25: =E23 | F25: Х | G25: =ROUND(C25*E25/100,2)
A26: 0202 | B26: дополнительная заработная плата | C26: ='2д план кальк (2)'!E35 | D26: Х | E26: =E23 | F26: Х | G26: =ROUND(C26*E26/100,2)
A27: 0300 | B27: Страховые взносы на обязательное социальное страхование | C27: ='2д план кальк (2)'!E36 | D27: Х | E27: =E23 | F27: Х | G27: =ROUND(C27*E27/100,2)
A28: 0400 | B28: Затраты на подготовку и освоение производства - всего: | C28: - | D28: - | E28: - | F28: - | G28: -
B29: в том числе:
A30: 0401 | B30: пусковые затраты | C30: - | D30: - | E30: - | F30: - | G30: -
A31: 0402 | B31: затраты на подготовку и освоение новых видов продукции | C31: - | D31: - | E31: - | F31: - | G31: -
A32: 0500 | B32: Затраты на специальную технологическую оснастку | C32: - | D32: - | E32: - | F32: - | G32: -
A33: 0600 | B33: Затраты на специальное оборудование для научных (экспериментальных) работ | C33: - | D33: - | E33: - | F33: - | G33: -
A34: 0700 | B34: Специальные затраты | C34: - | D34: - | E34: - | F34: - | G34: -
A35: 0800 | B35: Общепроизводственные затраты | C35: - | D35: Х | E35: - | F35: Х | G35: -
A36: 0900 | B36: Общехозяйственные затраты | C36: ='2д план кальк (2)'!E45 | D36: Х | E36: =E23 | F36: Х | G36: =ROUND(C36*E36/100,2)
A37: 1000 | B37: Затраты на командировки | C37: - | D37: Х | E37: - | F37: Х | G37: -
A38: 1100 | B38: Прочие прямые затраты | C38: - | D38: - | E38: - | F38: - | G38: -
A39: 1200 | B39: Затраты по работам (услугам), выполняемым (оказываемым) сторонними организациями | C39: Х | D39: - | E39: Х | F39: - | G39: -
A40: 1400 | B40: Коммерческие (внепроизводственные) затраты | C40: - | D40: - | E40: - | F40: - | G40: -
A41: 1500 | B41: Проценты по кредитам | C41: Х | D41: Х | E41: Х | F41: Х | G41: -
A42: 1600 | B42: Административно-управленческие расходы | C42: - | D42: Х | E42: - | F42: Х | G42: -
...

Sheet 20 (20д) приб (27г.)
A1: Форма № 20 (20д)
A3: Расчет и обоснование прибыли
A4: на 2027 г. по ТЕМА
A5: (наименование, шифр товара, работы, услуги)
G7: Таблица 1
A8: №№ строки | B8: Наименование статей затрат | C8: Затраты (руб.) | E8: Рентабельность (%) | G8: Величина прибыли (руб.)
C9: Собственные | D9: Привнесенные | E9: Собственные | F9: Привнесенные
A10: 1 | B10: 2 | C10: 3 | D10: 4 | E10: 5 | F10: 6 | G10: 7
A11: 0100 | B11: Материальные затраты - всего: | C11: Х | D11: - | E11: Х | F11: - | G11: -
B12: в том числе:
A13: 0101 | B13: приобретение сырья, материалов и вспомогательных материалов | C13: Х | D13: - | E13: Х | F13: - | G13: -
A14: 0102 | B14: приобретение полуфабрикатов | C14: Х | D14: - | E14: Х | F14: - | G14: -
A15: 0103 | B15: возвратные отходы | C15: - | D15: - | E15: - | F15: - | G15: -
A16: 0104 | B16: приобретение комплектующих изделий | C16: Х | D16: - | E16: Х | F16: - | G16: -
A17: 0105 | B17: оплата работ и услуг сторонних организаций производственного характера | C17: Х | D17: - | E17: Х | F17: - | G17: -
A18: 0106 | B18: транспортно-заготовительные затраты | C18: - | D18: - | E18: - | F18: - | G18: -
A19: 0107 | B19: топливо на технологические цели | C19: - | D19: - | E19: - | F19: - | G19: -
A20: 0108 | B20: энергия на технологические цели | C20: - | D20: - | E20: - | F20: - | G20: -
A21: 0109 | B21: тара и упаковка | C21: - | D21: - | E21: - | F21: - | G21: -
A22: 0110 | B22: затраты на изделия собственного производства | C22: - | D22: - | E22: - | F22: - | G22: -
A23: 0200 | B23: Затраты на оплату труда - всего: | C23: =C25+C26 | D23: Х | E23: 0 | F23: Х | G23: =G25+G26
B24: в том числе:
A25: 0201 | B25: основная заработная плата | C25: ='2д план кальк (2)'!I34 | D25: Х | E25: =E23 | F25: Х | G25: =ROUNDUP(C25*E25/100,2)
A26: 0202 | B26: дополнительная заработная плата | C26: ='2д план кальк (2)'!I35 | D26: Х | E26: =E23 | F26: Х | G26: =ROUND(C26*E26/100,2)
A27: 0300 | B27: Страховые взносы на обязательное социальное страхование | C27: ='2д план кальк (2)'!I36 | D27: Х | E27: =E23 | F27: Х | G27: =ROUND(C27*E27/100,2)
A28: 0400 | B28: Затраты на подготовку и освоение производства - всего: | C28: - | D28: - | E28: - | F28: - | G28: -
B29: в том числе:
A30: 0401 | B30: пусковые затраты | C30: - | D30: - | E30: - | F30: - | G30: -
A31: 0402 | B31: затраты на подготовку и освоение новых видов продукции | C31: - | D31: - | E31: - | F31: - | G31: -
A32: 0500 | B32: Затраты на специальную технологическую оснастку | C32: - | D32: - | E32: - | F32: - | G32: -
A33: 0600 | B33: Затраты на специальное оборудование для научных (экспериментальных) работ | C33: - | D33: - | E33: - | F33: - | G33: -
A34: 0700 | B34: Специальные затраты | C34: - | D34: - | E34: - | F34: - | G34: -
A35: 0800 | B35: Общепроизводственные затраты | C35: - | D35: Х | E35: - | F35: Х | G35: -
A36: 0900 | B36: Общехозяйственные затраты | C36: ='2д план кальк (2)'!I45 | D36: Х | E36: =E23 | F36: Х | G36: =ROUNDUP(C36*E36/100,2)
A37: 1000 | B37: Затраты на командировки | C37: - | D37: Х | E37: - | F37: Х | G37: -
A38: 1100 | B38: Прочие прямые затраты | C38: - | D38: - | E38: - | F38: - | G38: -
A39: 1200 | B39: Затраты по работам (услугам), выполняемым (оказываемым) сторонними организациями | C39: Х | D39: - | E39: Х | F39: - | G39: -
A40: 1400 | B40: Коммерческие (внепроизводственные) затраты | C40: - | D40: - | E40: - | F40: - | G40: -
A41: 1500 | B41: Проценты по кредитам | C41: Х | D41: Х | E41: Х | F41: Х | G41: -
A42: 1600 | B42: Административно-управленческие расходы | C42: - | D42: Х | E42: - | F42: Х | G42: -
...

Sheet 22 (22д) свед. о норм_25
D1: Форма № 22 (22д)
D3: УТВЕРЖДАЮ
D5: Проректор по научной работе ФГАОУ ВО «СПбПУ»
D6: __________________________ Ю.В. Фомин
D7: (подпись) (Ф.И.О.)
D8: «____» __________________ 2025 г.
A10: Сведения о нормативах и экономических показателях ФГАОУ ВО «СПбПУ», используемых при определении стоимости работ по договорам в рамках ГОЗ на 2025 год
A12: № п/п | B12: Наименование | C12: Единица измерения | D12: Значение | E12: Основание
A13: 1 | B13: 2 | C13: 3 | D13: 4 | E13: 5
A14: 1. | B14: Сведения по затратам на оплату труда:
A15: 1.1 | B15: среднемесячная заработная плата основных работников | C15: руб. | D15: 0 | E15: Письмо 550 ВП МО РФ № 115/550/238 от 05.05.2025г.
A16: 1.2 | B16: дополнительная заработная плата основных работников | C16: % | D16: 0 | E16: форма 10 (10д)
A17: 1.3 | B17: дополнительная заработная плата инженерно-технических и научных работников | C17: % | D17: 0 | E17: Приказ по ФГАОУ ВО "СПбПУ" о формировании отпускного фонда с 2018г.
A18: 1.4 | B18: дополнительная заработная плата профессорско-преподавательского состава | C18: % | D18: 0 | E18: Приказ по ФГАОУ ВО "СПбПУ" о формировании отпускного фонда с 2018г.
A19: 2. | B19: Отчисления от фонда оплаты труда: | C19: % | D19: =D20+D21
A20: 2.1 | B20: страховые взносы | C20: % | D20: 30
A21: 2.2 | B21: страховые взносы на обязательное страхование от несчастных случаев на производстве и профессиональных заболеваний | C21: % | D21: 0.2 | E21: уведомление ФСС
A22: 3. | B22: Общехозяйственные затраты (административно-управленческие расходы) / база распределения затрат (основная заработная плата) | C22: % | D22: 32 | E22: Письмо 550 ВП МО РФ № 115/550/238 от 05.05.2025г.
A23: 4. | B23: Общепроизводственные затраты / база распределения затрат (______________________________) | C23: % | D23: - | E23: -
A24: 5. | B24: Коммерческие (внепроизводственные) затраты / база распределения затрат (_________________________________________) | C24: % | D24: - | E24: -
A25: 6. | B25: Транспортно-заготовительные затраты / база распределения затрат (_________________________________________) | C25: % | D25: - | E25: -
A27: Начальник ОФЭАУ НИОКР ФГАОУ ВО «СПбПУ» | C27: _________________________ Н.О. Васецкая
C28: (подпись) (Ф.И.О.)
C29: «____» __________________ 2026 г.
A30: 1 В случае если этапы НИР (ОКР) выполняются в одном году, то формы, содержащие информацию о финансово-хозяйственной деятельности организации в целом (формы №№ 8 (8д), 10 (10д), 11 (11д), 12 (12д), 13 (13д), 21, 21д, 22 (22д), 23, 23д приложения № 5 к настоящему приказу), представляются единожды в составе соответствующего предложения о цене. При наличии различных уровней нормативов и экономических показателей для различных подразделений организации-потенциального поставщика (подрядчика, исполнителя) представляются сведения по каждому такому подразделению.
A31: 2 При проведении процедуры перевода в фиксированную цену других видов цен на продукцию организацией указываются значения, используемые при определении фиксированной цены в соответствии с установленными в государственном контракте (контракте) условиями уточнения и порядка перевода соответствующего вида цены на продукцию в фиксированную цену. В случае если технологический цикл производства продукции составляет более 1 года либо год начала производства продукции не соответствует году окончания ее производства и поставки (или завершения отдельных этапов поставки продукции, если государственным контрактом (контрактом) предусмотрены такие этапы), то организация представляет сведения с разбивкой по годам для указания информации.
A32: 3 С указанием наименования и реквизитов подтверждающих (обосновывающих) документов (при наличии).
A33: 4 Указывается используемая единица измерения трудоемкости: нормо-час / человеко-час / человеко-день / человеко-месяц.
A34: 5 К основным работникам относятся основные производственные рабочие, инженерно-технические и другие категории работников, непосредственно участвующие в процессе производства продукции, согласно порядку определения состава затрат, включаемых в цену продукции, поставляемой в рамках государственного оборонного заказа, утвержденному в соответствии с постановлением Правительства Российской Федерации от 2 декабря 2017 года № 1465 "О государственном регулировании цен на продукцию, поставляемую по государственному оборонному заказу, а также о внесении изменений и признании утратившими силу некоторых актов Правительства Российской Федерации".
A35: 6 Указывается метод распределения затрат в соответствии с принятой на предприятии учетной политикой на соответствующий год.
A37: Используемые сокращения и их расшифровка:
B38: ИТР – инженерно-технический работник; НИР (ОКР) – научно-исследовательская работа (опытно-конструкторская работа).

Sheet 22 (22д) свед. о норм_26
D1: Форма № 22 (22д)
E3: УТВЕРЖДАЮ
E5: Проректор по научной работе ФГАОУ ВО «СПбПУ»
E6: __________________________ Ю.В. Фомин
E7: (подпись) (Ф.И.О.)
E8: «____» __________________ 2026 г.
A10: Сведения о нормативах и экономических показателях ФГАОУ ВО «СПбПУ», используемых при определении стоимости работ по договорам в рамках ГОЗ на 2026 год
A12: № п/п | B12: Наименование | C12: Единица измерения | D12: Значение | E12: Основание
A13: 1 | B13: 2 | C13: 3 | D13: 4 | E13: 5
A14: 1. | B14: Сведения по затратам на оплату труда:
A15: 1.1 | B15: среднемесячная заработная плата основных работников | C15: руб. | D15: 112261 | E15: Письмо 550 ВП МО РФ № 115/550/231/1 от 25.05.2026г.
A16: 1.2 | B16: дополнительная заработная плата основных работников | C16: % | D16: 8.6866 | E16: форма 10 (10д)
A17: 1.3 | B17: дополнительная заработная плата инженерно-технических и научных работников | C17: % | D17: 0 | E17: Приказ по ФГАОУ ВО "СПбПУ" о формировании отпускного фонда с 2018г.
A18: 1.4 | B18: дополнительная заработная плата профессорско-преподавательского состава | C18: % | D18: 0 | E18: Приказ по ФГАОУ ВО "СПбПУ" о формировании отпускного фонда с 2018г.
A19: 2. | B19: Отчисления от фонда оплаты труда: | C19: % | D19: =D20+D21
A20: 2.1 | B20: страховые взносы | C20: % | D20: 30
A21: 2.2 | B21: страховые взносы на обязательное страхование от несчастных случаев на производстве и профессиональных заболеваний | C21: % | D21: 0.2 | E21: уведомление ФСС
A22: 3. | B22: Общехозяйственные затраты (административно-управленческие расходы) / база распределения затрат (основная заработная плата) | C22: % | D22: 0 | E22: Письмо 550 ВП МО РФ № 115/550/231/1 от 25.05.2026г.
A23: 4. | B23: Общепроизводственные затраты / база распределения затрат (______________________________) | C23: % | D23: - | E23: -
A24: 5. | B24: Коммерческие (внепроизводственные) затраты / база распределения затрат (_________________________________________) | C24: % | D24: - | E24: -
A25: 6. | B25: Транспортно-заготовительные затраты / база распределения затрат (_________________________________________) | C25: % | D25: - | E25: -
A27: Начальник ОФЭАУ НИОКР ФГАОУ ВО «СПбПУ» | C27: _________________________ Н.О. Васецкая
C28: (подпись) (Ф.И.О.)
C29: «____» __________________ 2026 г.
A30: 1 В случае если этапы НИР (ОКР) выполняются в одном году, то формы, содержащие информацию о финансово-хозяйственной деятельности организации в целом (формы №№ 8 (8д), 10 (10д), 11 (11д), 12 (12д), 13 (13д), 21, 21д, 22 (22д), 23, 23д приложения № 5 к настоящему приказу), представляются единожды в составе соответствующего предложения о цене. При наличии различных уровней нормативов и экономических показателей для различных подразделений организации-потенциального поставщика (подрядчика, исполнителя) представляются сведения по каждому такому подразделению.
A31: 2 При проведении процедуры перевода в фиксированную цену других видов цен на продукцию организацией указываются значения, используемые при определении фиксированной цены в соответствии с установленными в государственном контракте (контракте) условиями уточнения и порядка перевода соответствующего вида цены на продукцию в фиксированную цену. В случае если технологический цикл производства продукции составляет более 1 года либо год начала производства продукции не соответствует году окончания ее производства и поставки (или завершения отдельных этапов поставки продукции, если государственным контрактом (контрактом) предусмотрены такие этапы), то организация представляет сведения с разбивкой по годам для указания информации.
A32: 3 С указанием наименования и реквизитов подтверждающих (обосновывающих) документов (при наличии).
A33: 4 Указывается используемая единица измерения трудоемкости: нормо-час / человеко-час / человеко-день / человеко-месяц.
A34: 5 К основным работникам относятся основные производственные рабочие, инженерно-технические и другие категории работников, непосредственно участвующие в процессе производства продукции, согласно порядку определения состава затрат, включаемых в цену продукции, поставляемой в рамках государственного оборонного заказа, утвержденному в соответствии с постановлением Правительства Российской Федерации от 2 декабря 2017 года № 1465 "О государственном регулировании цен на продукцию, поставляемую по государственному оборонному заказу, а также о внесении изменений и признании утратившими силу некоторых актов Правительства Российской Федерации".
A35: 6 Указывается метод распределения затрат в соответствии с принятой на предприятии учетной политикой на соответствующий год.
A37: Используемые сокращения и их расшифровка:
B38: ИТР – инженерно-технический работник; НИР (ОКР) – научно-исследовательская работа (опытно-конструкторская работа).

Sheet 22 (22д) свед. о норм_27
D1: Форма № 22 (22д)
D3: УТВЕРЖДАЮ
D5: Проректор по научной работе ФГАОУ ВО «СПбПУ»
D6: __________________________ Ю.В. Фомин
D7: (подпись) (Ф.И.О.)
D8: «____» __________________ 2026 г.
A10: Сведения о нормативах и экономических показателях ФГАОУ ВО «СПбПУ», используемых при определении стоимости работ по договорам в рамках ГОЗ на 2027 год
A12: № п/п | B12: Наименование | C12: Единица измерения | D12: Значение | E12: Основание
A13: 1 | B13: 2 | C13: 3 | D13: 4 | E13: 5
A14: 1. | B14: Сведения по затратам на оплату труда:
A15: 1.1 | B15: среднемесячная заработная плата основных работников | C15: руб. | D15: =ROUND('22 (22д) свед. о норм_26'!D15*1.04*1.039,0) | E15: Норматив 2026 с учетом письма Мин.эконом.развития №37099-ПК/Д03и от 30.09.2025 применены индексы: 2027 ИПЦ-1,04 и ИРЗП-1,039
A16: 1.2 | B16: дополнительная заработная плата основных работников | C16: % | D16: 0 | E16: форма 10 (10д)
A17: 1.3 | B17: дополнительная заработная плата инженерно-технических и научных работников | C17: % | D17: 0 | E17: Приказ по ФГАОУ ВО "СПбПУ" о формировании отпускного фонда с 2018г.
A18: 1.4 | B18: дополнительная заработная плата профессорско-преподавательского состава | C18: % | D18: 0 | E18: Приказ по ФГАОУ ВО "СПбПУ" о формировании отпускного фонда с 2018г.
A19: 2. | B19: Отчисления от фонда оплаты труда: | C19: % | D19: =D20+D21
A20: 2.1 | B20: страховые взносы | C20: % | D20: 30
A21: 2.2 | B21: страховые взносы на обязательное страхование от несчастных случаев на производстве и профессиональных заболеваний | C21: % | D21: 0.2 | E21: уведомление ФСС
A22: 3. | B22: Общехозяйственные затраты (административно-управленческие расходы) / база распределения затрат (основная заработная плата) | C22: % | D22: 32 | E22: форма 12
A23: 4. | B23: Общепроизводственные затраты / база распределения затрат (______________________________) | C23: % | D23: - | E23: -
A24: 5. | B24: Коммерческие (внепроизводственные) затраты / база распределения затрат (_________________________________________) | C24: % | D24: - | E24: -
A25: 6. | B25: Транспортно-заготовительные затраты / база распределения затрат (_________________________________________) | C25: % | D25: - | E25: -
A27: Начальник ОФЭАУ НИОКР ФГАОУ ВО «СПбПУ» | C27: _________________________ Н.О. Васецкая
C28: (подпись) (Ф.И.О.)
C29: «____» __________________ 2026 г.
A31: 1 В случае если этапы НИР (ОКР) выполняются в одном году, то формы, содержащие информацию о финансово-хозяйственной деятельности организации в целом (формы №№ 8 (8д), 10 (10д), 11 (11д), 12 (12д), 13 (13д), 21, 21д, 22 (22д), 23, 23д приложения № 5 к настоящему приказу), представляются единожды в составе соответствующего предложения о цене. При наличии различных уровней нормативов и экономических показателей для различных подразделений организации-потенциального поставщика (подрядчика, исполнителя) представляются сведения по каждому такому подразделению.
A32: 2 При проведении процедуры перевода в фиксированную цену других видов цен на продукцию организацией указываются значения, используемые при определении фиксированной цены в соответствии с установленными в государственном контракте (контракте) условиями уточнения и порядка перевода соответствующего вида цены на продукцию в фиксированную цену. В случае если технологический цикл производства продукции составляет более 1 года либо год начала производства продукции не соответствует году окончания ее производства и поставки (или завершения отдельных этапов поставки продукции, если государственным контрактом (контрактом) предусмотрены такие этапы), то организация представляет сведения с разбивкой по годам для указания информации.
A33: 3 С указанием наименования и реквизитов подтверждающих (обосновывающих) документов (при наличии).
A34: 4 Указывается используемая единица измерения трудоемкости: нормо-час / человеко-час / человеко-день / человеко-месяц.
A35: 5 К основным работникам относятся основные производственные рабочие, инженерно-технические и другие категории работников, непосредственно участвующие в процессе производства продукции, согласно порядку определения состава затрат, включаемых в цену продукции, поставляемой в рамках государственного оборонного заказа, утвержденному в соответствии с постановлением Правительства Российской Федерации от 2 декабря 2017 года № 1465 "О государственном регулировании цен на продукцию, поставляемую по государственному оборонному заказу, а также о внесении изменений и признании утратившими силу некоторых актов Правительства Российской Федерации".
A36: 6 Указывается метод распределения затрат в соответствии с принятой на предприятии учетной политикой на соответствующий год.
A38: Используемые сокращения и их расшифровка:
B39: ИТР – инженерно-технический работник; НИР (ОКР) – научно-исследовательская работа (опытно-конструкторская работа).

Sheet 10 (10д) ДЗП (КФО2) (25-27)
H1: Форма № 10 (10д)
B3: Расчет-обоснование уровня (%) дополнительной заработной платы основных работников попо приносящей доход деятельности (КФО 2) на 2025-2027 гг
B4: по ФГАОУ ВО «Санкт-Петербургский политехнический университет Петра Великого»
B5: (наименование организации-поставщика (подрядчика, исполнителя))
H6: (руб.)
A7: № п/п | B7: Наименование | C7: Период, предшествующий отчетному (2023 г.) | D7: Отчетный период / период, предшествующий планируемому (2024 г.) | F7: Планируемый период (2025 г.) | G7: Планируемый период (2026 г.) | H7: Планируемый период (2027 г.)
C8: факт | D8: план | E8: факт | F8: план | G8: план | H8: план
A9: 1 | B9: 2 | C9: 3 | D9: 4.1 | E9: 4.2 | F9: 5 | G9: 6 | H9: 7
A10: 1. | B10: Основная заработная плата основных работников | C10: 0 | D10: 0 | E10: 0 | F10: 0 | G10: 0 | H10: 0
A11: 2. | B11: Дополнительная заработная плата основных работников, | C11: 0 | D11: 0 | E11: 0 | F11: 0 | G11: 0 | H11: 0
A12: 2.1 | B12: в % к основной заработной плате основных работников, % | C12: =C11/C10 | D12: =D11/D10 | E12: =E11/E10 | F12: =F11/F10 | G12: =G11/G10 | H12: =H11/H10
A14: Структура дополнительной заработной платы
H15: (руб.)
A16: № п/п | B16: Наименование выплат | C16: Период, предшествующий отчетному (2023 г.) | D16: Отчетный период / период, предшествующий планируемому (2024 г.) | F16: Планируемый период (2025 г.) | G16: Планируемый период (2026 г.) | H16: Планируемый период (2027 г.)
C17: факт | D17: план | E17: факт | F17: план | G17: план | H17: план
A18: 1 | B18: 2 | C18: 3 | D18: 4.1 | E18: 4.2 | F18: 5 | G18: 6 | H18: 7
A19: 1. | B19: Выплаты отпусков работникам из резервного отпускного фонда | C19: =C11 | D19: =D11 | E19: =E11 | F19: =F11 | G19: =G11 | H19: =H11
A20: ИТОГО | C20: =C19 | D20: =D19 | E20: =E19 | F20: =F19 | G20: =G19 | H20: =H19
B22: Начальник ОФЭАУ НИОКР | F22: Главный бухгалтер ФГАОУ ВО «СПБПУ»
B23: __________________________ Н.О. Васецкая | F23: ________________________ Н.В. Иванова
B24: (подпись) (Ф.И.О.) | F24: (подпись) (Ф.И.О.)
B25: «____» __________________ 2026 г. | F25: «____» __________________ 2026 г.
A27: 1 При наличии различных уровней дополнительной заработной платы основных работников для различных подразделений организации-потенциального поставщика (подрядчика, исполнителя) представляются расчеты-обоснования по каждому такому подразделению.
A28: 2 К основным работникам относятся основные производственные рабочие, инженерно-технические и другие категории работников, непосредственно участвующие в процессе производства продукции, согласно порядку определения состава затрат, включаемых в цену продукции, поставляемой в рамках государственного оборонного заказа, утвержденному в соответствии с постановлением Правительства Российской Федерации от 2 декабря 2017 года № 1465 "О государственном регулировании цен на продукцию, поставляемую по государственному оборонному заказу, а также о внесении изменений и признании утратившими силу некоторых актов Правительства Российской Федерации".
A29: 3 В случае если технологический цикл производства продукции составляет более 1 года либо год начала производства продукции не соответствует году окончания ее производства и поставки (или завершения отдельных этапов поставки продукции, если государственным контрактом (контрактом) предусмотрены такие этапы), то организация представляет сведения по годам.
A30: 4 В случае если этапы НИР (ОКР) выполняются в одном году, то формы, содержащие информацию о финансово-хозяйственной деятельности организации в целом (формы №№ 8 (8д), 10 (10д), 11 (11д), 12 (12д), 13 (13д), 21, 21д, 22 (22д), 23, 23д приложения № 5 к настоящему приказу), представляются единожды в составе соответствующего предложения о цене.
A31: 5 При проведении процедуры перевода в фиксированную цену других видов цен на продукцию организацией с учетом установленных в государственном контракте (контракте) условий уточнения и порядка перевода соответствующего вида цены на продукцию в фиксированную цену в графе 5 представляются планируемые затраты года окончания поставки продукции в рамках выполнения государственного контракта (контракта) (или завершения отдельных этапов поставки продукции, если государственным контрактом (контрактом) предусмотрены такие этапы). В случае если технологический цикл производства продукции составляет более 1 года либо год начала производства продукции не соответствует году окончания ее производства и поставки (или завершения отдельных этапов поставки продукции, если государственным контрактом (контрактом) предусмотрены такие этапы), то организация представляет сведения о затратах по годам, предшествующим году поставки продукции, в соответствии с графами 4.1-4.2 на каждый год производства продукции, дополнив форму после графы 4.2 графами, аналогичными по содержанию графам 4.1-4.2 соответственно (с последующей корректировкой нумерации граф), для указания информации.
A32: 6 Указываются выплаты, предусмотренные локальным нормативным актом организации или нормативным правовым актом Российской Федерации, а также представляется такой локальный нормативный акт или оформляется ссылка на конкретную структурную единицу нормативных правовых актов Российской Федерации, являющихся основанием указанных выплат за счет фонда дополнительной заработной платы из состава себестоимости организации; при удельном весе более 10 процентов представляется расшифровка выплат.
A34: Используемые сокращения и их расшифровка:
B35: ГОЗ – государственный оборонный заказ; НИР (ОКР) – научно-исследовательская работа (опытно-конструкторская работа).

Sheet 10 (10д) ДЗП (ГОЗ) (25-27)
H1: Форма № 10 (10д)
B3: Расчет-обоснование уровня (%) дополнительной заработной платы основных работников по договорам в рамках ГОЗ на 2025-2027 гг
B4: по ФГАОУ ВО «Санкт-Петербургский политехнический университет Петра Великого»
B5: (наименование организации-поставщика (подрядчика, исполнителя))
H6: (руб.)
A7: № п/п | B7: Наименование | C7: Период, предшествующий отчетному (2023 г.) | D7: Отчетный период / период, предшествующий планируемому (2024 г.) | F7: Планируемый период (2025 г.) | G7: Планируемый период (2026 г.) | H7: Планируемый период (2027 г.)
C8: факт | D8: план | E8: факт | F8: план | G8: план | H8: план
A9: 1 | B9: 2 | C9: 3 | D9: 4.1 | E9: 4.2 | F9: 5 | G9: 6 | H9: 7
A10: 1. | B10: Основная заработная плата основных работников | C10: 0 | D10: 0 | E10: 0 | F10: 0 | G10: 0 | H10: 0
A11: 2. | B11: Дополнительная заработная плата основных работников, | C11: 0 | D11: 0 | E11: 0 | F11: 0 | G11: 0 | H11: 0
A12: 2.1 | B12: в % к основной заработной плате основных работников, % | C12: =C11/C10 | D12: =D11/D10 | E12: =E11/E10 | F12: =F11/F10 | G12: =G11/G10 | H12: =H11/H10
A14: Структура дополнительной заработной платы
H15: (руб.)
A16: № п/п | B16: Наименование выплат | C16: Период, предшествующий отчетному (2023 г.) | D16: Отчетный период / период, предшествующий планируемому (2024 г.) | F16: Планируемый период (2025 г.) | G16: Планируемый период (2026 г.) | H16: Планируемый период (2027 г.)
C17: факт | D17: план | E17: факт | F17: план | G17: план | H17: план
A18: 1 | B18: 2 | C18: 3 | D18: 4.1 | E18: 4.2 | F18: 5 | G18: 6 | H18: 7
A19: 1. | B19: Выплаты отпусков работникам из резервного отпускного фонда | C19: =C11 | D19: =D11 | E19: =E11 | F19: =F11 | G19: =G11 | H19: =H11
A20: ИТОГО | C20: =C19 | D20: =D19 | E20: =E19 | F20: =F19 | G20: =G19 | H20: =H19
B22: Начальник ОФЭАУ НИОКР | F22: Главный бухгалтер ФГАОУ ВО «СПБПУ»
B23: __________________________ Н.О. Васецкая | F23: ________________________ Н.В. Иванова
B24: (подпись) (Ф.И.О.) | F24: (подпись) (Ф.И.О.)
B25: «____» __________________ 2026 г. | F25: «____» __________________ 2026 г.
A27: 1 При наличии различных уровней дополнительной заработной платы основных работников для различных подразделений организации-потенциального поставщика (подрядчика, исполнителя) представляются расчеты-обоснования по каждому такому подразделению.
A28: 2 К основным работникам относятся основные производственные рабочие, инженерно-технические и другие категории работников, непосредственно участвующие в процессе производства продукции, согласно порядку определения состава затрат, включаемых в цену продукции, поставляемой в рамках государственного оборонного заказа, утвержденному в соответствии с постановлением Правительства Российской Федерации от 2 декабря 2017 года № 1465 "О государственном регулировании цен на продукцию, поставляемую по государственному оборонному заказу, а также о внесении изменений и признании утратившими силу некоторых актов Правительства Российской Федерации".
A29: 3 В случае если технологический цикл производства продукции составляет более 1 года либо год начала производства продукции не соответствует году окончания ее производства и поставки (или завершения отдельных этапов поставки продукции, если государственным контрактом (контрактом) предусмотрены такие этапы), то организация представляет сведения по годам.
A30: 4 В случае если этапы НИР (ОКР) выполняются в одном году, то формы, содержащие информацию о финансово-хозяйственной деятельности организации в целом (формы №№ 8 (8д), 10 (10д), 11 (11д), 12 (12д), 13 (13д), 21, 21д, 22 (22д), 23, 23д приложения № 5 к настоящему приказу), представляются единожды в составе соответствующего предложения о цене.
A31: 5 При проведении процедуры перевода в фиксированную цену других видов цен на продукцию организацией с учетом установленных в государственном контракте (контракте) условий уточнения и порядка перевода соответствующего вида цены на продукцию в фиксированную цену в графе 5 представляются планируемые затраты года окончания поставки продукции в рамках выполнения государственного контракта (контракта) (или завершения отдельных этапов поставки продукции, если государственным контрактом (контрактом) предусмотрены такие этапы). В случае если технологический цикл производства продукции составляет более 1 года либо год начала производства продукции не соответствует году окончания ее производства и поставки (или завершения отдельных этапов поставки продукции, если государственным контрактом (контрактом) предусмотрены такие этапы), то организация представляет сведения о затратах по годам, предшествующим году поставки продукции, в соответствии с графами 4.1-4.2 на каждый год производства продукции, дополнив форму после графы 4.2 графами, аналогичными по содержанию графам 4.1-4.2 соответственно (с последующей корректировкой нумерации граф), для указания информации.
A32: 6 Указываются выплаты, предусмотренные локальным нормативным актом организации или нормативным правовым актом Российской Федерации, а также представляется такой локальный нормативный акт или оформляется ссылка на конкретную структурную единицу нормативных правовых актов Российской Федерации, являющихся основанием указанных выплат за счет фонда дополнительной заработной платы из состава себестоимости организации; при удельном весе более 10 процентов представляется расшифровка выплат.
A34: Используемые сокращения и их расшифровка:
B35: ГОЗ – государственный оборонный заказ; НИР (ОКР) – научно-исследовательская работа (опытно-конструкторская работа).

Sheet 12 ОХР (КФО2_ГОЗ) (25-27)
O1: Форма № 12
B3: Смета и расчет
B4: общехозяйственных затрат по приносящей доход деятельности (КФО 2) на 2025-2027 гг по ФГАОУ ВО «Санкт-Петербургский политехнический университет Петра Великого»
B5: (наименование организации-поставщика (подрядчика, исполнителя))
O6: (руб.)
A7: № п/п | B7: Наименование статей | C7: Отчетный период / период, предшествующий планируемому (год 2024) | G7: применяемый индекс цен | H7: Планируемый период (год 2025) | J7: применяемый индекс цен | K7: Планируемый период (год 2026) | M7: применяемый индекс цен5 | N7: Планируемый период (год 2027)
C8: план | E8: факт | H8: предложено организацией-поставщиком (подрядчиком, исполнителем) | K8: предложено организацией-поставщиком (подрядчиком, исполнителем) | N8: предложено организацией-поставщиком (подрядчиком, исполнителем)
C9: всего | D9: в том числе по госконтрактам (контрактам) ГОЗ | E9: всего | F9: в том числе по госконтрактам (контрактам) ГОЗ | H9: всего | I9: в том числе по госконтрактам (контрактам) ГОЗ | K9: всего | L9: в том числе по госконтрактам (контрактам) ГОЗ | N9: всего | O9: в том числе по госконтрактам (контрактам) ГОЗ
A10: 1 | B10: 2 | C10: 3 | D10: 4 | E10: 5 | F10: 6 | G10: 7 | H10: 8 | I10: 9 | J10: 10 | K10: 11 | L10: 12 | M10: 13 | N10: 14 | O10: 15
A11: 1 | B11: 211 Заработная плата | C11: 0 | D11: 0 | E11: 0 | F11: 0 | H11: 0 | I11: 0 | K11: 0 | L11: 0 | N11: 0 | O11: 0
A12: 2 | B12: 212 Прочие выплаты | C12: 0 | D12: 0 | E12: 0 | F12: 0 | H12: 0 | I12: 0 | K12: 0 | L12: 0 | N12: 0 | O12: 0
A13: 3 | B13: 213 Начисления на оплату труда | C13: 0 | D13: 0 | E13: 0 | F13: 0 | H13: 0 | I13: 0 | K13: 0 | L13: 0 | N13: 0 | O13: 0
A14: 4 | B14: 221 Услуги связи | C14: 0 | D14: 0 | E14: 0 | F14: 0 | H14: 0 | I14: 0 | K14: 0 | L14: 0 | N14: 0 | O14: 0
A15: 5 | B15: 222 Транспортные услуги | C15: 0 | D15: 0 | E15: 0 | F15: 0 | H15: 0 | I15: 0 | K15: 0 | L15: 0 | N15: 0 | O15: 0
A16: 6 | B16: 223 Коммунальные услуги | C16: 0 | D16: 0 | E16: 0 | F16: 0 | H16: 0 | I16: 0 | K16: 0 | L16: 0 | N16: 0 | O16: 0
A17: 7 | B17: 224 Арендная плата за пользование имуществом | C17: 0 | D17: 0 | E17: 0 | F17: 0 | H17: 0 | I17: 0 | K17: 0 | L17: 0 | N17: 0 | O17: 0
A18: 8 | B18: 225 Услуги по содержанию имущества | C18: 0 | D18: 0 | E18: 0 | F18: 0 | H18: 0 | I18: 0 | K18: 0 | L18: 0 | N18: 0 | O18: 0
A19: 9 | B19: 226 Прочие услуги | C19: 0 | D19: 0 | E19: 0 | F19: 0 | H19: 0 | I19: 0 | K19: 0 | L19: 0 | N19: 0 | O19: 0
A20: 10 | B20: 226 Расходы на амортизацию прав пользования НМА | C20: 0 | D20: 0 | E20: 0 | F20: 0 | H20: 0 | I20: 0 | K20: 0 | L20: 0 | N20: 0 | O20: 0
A21: 11 | B21: 227 Страхование | C21: 0 | D21: 0 | E21: 0 | F21: 0 | H21: 0 | I21: 0 | K21: 0 | L21: 0 | N21: 0 | O21: 0
A22: 13 | B22: 266 Социальные пособия и компенсации персоналу в денежной форме | C22: 0 | D22: 0 | E22: 0 | F22: 0 | H22: 0 | I22: 0 | K22: 0 | L22: 0 | N22: 0 | O22: 0
... A26: 17 | B26: 297 Иные выплаты текущего характера организациям | C26: 0 | D26: 0 | E26: 0 | F26: 0 | H26: 0 | I26: 0 | K26: 0 | L26: 0 | N26: 0 | O26: 0
A27: ИТОГО | C27: =SUM(C11:C26) | D27: =SUM(D11:D26) | E27: =SUM(E11:E26) | F27: =SUM(F11:F26) | H27: =SUM(H11:H26) | I27: =SUM(I11:I26) | K27: =SUM(K11:K26) | L27: =SUM(L11:L26) | N27: =SUM(N11:N26) | O27: =SUM(O11:O26)
A28: База распределения общехозяйственных затрат / административно-управленческих расходов (основная заработная плата)6 | C28: 0 | D28: 0 | E28: 0 | F28: 0 | H28: 0 | I28: 0 | K28: 0 | L28: 0 | N28: 0 | O28: 0
A29: Отношение общехозяйственных затрат / административно-управленческих расходов к базе распределения, % | C29: =C27/C28 | D29: =D27/D28 | E29: =E27/E28 | F29: =F27/F28 | H29: =H27/H28 | I29: =I27/I28 | K29: =K27/K28 | L29: =L27/L28 | N29: =N27/N28 | O29: =O27/O28
B31: Начальник ОФЭАУ НИОКР | I31: Главный бухгалтер ФГАОУ ВО «СПБПУ»
B32: __________________________ Н.О. Васецкая | I32: __________________________ Н.В. Иванова
B33: (подпись) (Ф.И.О.) | I33: (подпись) (Ф.И.О.)
B34: «____» __________________ 2026 г. | I34: «____» __________________ 2026 г.
A36: 1 Административно-управленческие расходы применяются в случае если учётной политикой организации расходы, связанные с управлением деятельностью организации в целом, признаются расходами отчетного периода, в котором они возникли, и предусмотрено отнесение указанных затрат на финансовый результат государственного контракта (контракта) (согласно порядку определения состава затрат, включаемых в цену продукции, поставляемой в рамках государственного оборонного заказа, утвержденному в соответствии с постановлением Правительства Российской Федерации от 2 декабря 2017 года № 1465 "О государственном регулировании цен на продукцию, поставляемую по государственному оборонному заказу, а также о внесении изменений и признании утратившими силу некоторых актов Правительства Российской Федерации" (далее - Порядок)). При наличии различных уровней общехозяйственных затрат / административно-управленческих расходов для различных подразделений организации-потенциального поставщика (подрядчика, исполнителя) представляются сметы в целом по организации и по каждому такому подразделению.
A37: 2 В случае если этапы НИР (ОКР) выполняются в одном году, то формы, содержащие информацию о финансово-хозяйственной деятельности организации в целом (формы №№ 8 (8д), 10 (10д), 11 (11д), 12 (12д), 13 (13д), 21, 21д, 22 (22д), 23, 23д приложения № 5 к настоящему приказу), представляются единожды в составе соответствующего предложения о цене.
A38: 3 Представляются по статьям затрат согласно Порядку.
A39: 4 При проведении процедуры перевода в фиксированную цену других видов цен на продукцию организацией с учетом установленных в государственном контракте (контракте) условий уточнения и порядка перевода соответствующего вида цены на продукцию в фиксированную цену в графах 8-9 представляются планируемые затраты года окончания поставки продукции в рамках выполнения государственного контракта (контракта) (или завершения отдельных этапов поставки продукции, если государственным контрактом (контрактом) предусмотрены такие этапы). В случае если технологический цикл производства продукции составляет более 1 года либо год начала производства продукции не соответствует году окончания ее производства и поставки (или завершения отдельных этапов поставки продукции, если государственным контрактом (контрактом) предусмотрены такие этапы), то организация представляет сведения о затратах по годам, предшествующим году поставки продукции, в соответствии с графами 3-6 на каждый год производства продукции, дополнив форму после графы 6 графами, аналогичными по содержанию графам 3-6 соответственно (с последующей корректировкой нумерации граф), для указания информации.
A40: 5 В пояснительной записке, прилагаемой к соответствующему предложению о цене, организацией представляется обоснование применяемого индекса цен (в случае использования).
A41: 6 Указывается метод распределения затрат согласно Порядку.
A43: Используемые сокращения и их расшифровка:
B44: ГОЗ – государственный оборонный заказ; НИР (ОКР) – научно-исследовательская работа (опытно-конструкторская работа).

Sheet 21 свед. об V поставки (25-27)
V1: Форма № 21
B3: Сведения об объемах поставки продукции, в том числе по государственному оборонному заказу, включая экспортные поставки
B4: ФГАОУ ВО «Санкт-Петербургский политехнический университет Петра Великого»
A5: (наименование организации-поставщика (подрядчика, исполнителя))
A7: № строки | B7: Наименование | C7: Единица измерения | D7: Отчет за n-ый год (2024 г.) | L7: Предусмотрено бизнес-планом на 2025 г. | P7: Предусмотрено бизнес-планом на 2026 г. | T7: Предусмотрено бизнес-планом на 2027 г.
D8: в целом по предприятию | H8: в том числе по государственным контрактам (контрактам) ГОЗ | L8: в целом по предприятию | N8: в том числе по государственным контрактам (контрактам) ГОЗ | P8: в целом по предприятию | R8: в том числе по государственным контрактам (контрактам) ГОЗ | T8: в целом по предприятию | V8: в том числе по государственным контрактам (контрактам) ГОЗ
D9: план | E9: в том числе на экспорт | F9: факт | G9: в том числе на экспорт | H9: план | I9: в том числе на экспорт | J9: факт | K9: в том числе на экспорт | L9: план | M9: в том числе на экспорт | N9: план | O9: в том числе на экспорт | P9: план | Q9: в том числе на экспорт | R9: план | S9: в том числе на экспорт | T9: план | U9: в том числе на экспорт | V9: план | W9: в том числе на экспорт
A10: 1 | B10: 2 | C10: 3 | D10: 4 | E10: 5 | F10: 6 | G10: 7 | H10: 8 | I10: 9 | J10: 10 | K10: 11 | L10: 12 | M10: 13 | N10: 14 | O10: 15 | P10: 16 | Q10: 17 | R10: 18 | S10: 19 | T10: 20 | U10: 21 | V10: 22 | W10: 23
A11: 1. | B11: Выручка (нетто) от реализации продукции (без НДС) | C11: тыс. руб. | D11: 0 | E11: Х | F11: 0 | G11: Х | H11: 0 | I11: Х | J11: 0 | K11: Х | L11: 0 | M11: Х | N11: 0 | O11: Х | P11: 0 | Q11: Х | R11: 0 | S11: Х | T11: 0 | U11: Х | V11: 0 | W11: Х
A12: 2. | B12: Финансовый результат (+ прибыль/ - убыток) от реализации продукции | C12: тыс. руб. | D12: =D11-D22 | E12: Х | F12: =F11-F22 | G12: Х | H12: X | I12: Х | J12: X | K12: Х | L12: =L11-L22 | M12: Х | N12: X | O12: Х | P12: =P11-P22 | Q12: Х | R12: X | S12: Х | T12: =T11-T22 | U12: Х | V12: X | W12: Х
A13: 2.1 | B13: валовая прибыль (убыток) | C13: тыс. руб. | D13: 0 | E13: Х | G13: Х | H13: X | I13: Х | J13: X | K13: Х | M13: Х | N13: X | O13: Х | Q13: Х | R13: X | S13: Х | U13: Х | V13: X | W13: Х
A14: 2.2 | B14: прибыль (убыток) от продаж | C14: тыс. руб. | D14: 0 | E14: Х | G14: Х | H14: X | I14: Х | J14: X | K14: Х | M14: Х | N14: X | O14: Х | Q14: Х | R14: X | S14: Х | U14: Х | V14: X | W14: Х
A15: 2.3 | B15: прибыль (убыток) до налогообложения | C15: тыс. руб. | D15: =D12 | E15: Х | F15: 0 | G15: Х | H15: X | I15: Х | J15: X | K15: Х | L15: =L12 | M15: Х | N15: X | O15: Х | P15: =P12 | Q15: Х | R15: X | S15: Х | T15: =T12 | U15: Х | V15: X | W15: Х
A16: 2.4 | B16: чистая прибыль (убыток) | C16: тыс. руб. | D16: =D15*0.8 | E16: Х | F16: 0 | G16: Х | H16: X | I16: Х | J16: X | K16: Х | L16: 0 | M16: Х | N16: X | O16: Х | P16: 0 | Q16: Х | R16: X | S16: Х | T16: 0 | U16: Х | V16: X | W16: Х
A17: 3. | B17: Уровень рентабельности | E17: Х | G17: Х | H17: X | I17: Х | J17: X | K17: Х | M17: Х | N17: X | O17: Х | Q17: Х | R17: X | S17: Х | U17: Х | V17: X | W17: Х
A18: 3.1 | B18: строка 2.1 / строка 4 | C18: % | D18: =D13/D22 | E18: Х | G18: Х | H18: X | I18: Х | J18: X | K18: Х | M18: Х | N18: X | O18: Х | Q18: Х | R18: X | S18: Х | U18: Х | V18: X | W18: Х
A19: 3.2 | B19: строка 2.2 / строка 4 | C19: % | D19: =D14/D22 | E19: Х | G19: Х | H19: X | I19: Х | J19: X | K19: Х | M19: Х | N19: X | O19: Х | Q19: Х | R19: X | S19: Х | U19: Х | V19: X | W19: Х
