Workbook
Name _Hlk532895363: Накладные!#REF!
Name _Hlk68180980: Амортизация!$B$6
Name _Hlk68180980: Стор_орг!$B$6
Name договор: '[1]структура цены'!$A$3
Name договор: 'Структура цены'!#REF!
Name тема: 'Структура цены'!$A$2

Sheet Структура цены
A1: СТРУКТУРА ЦЕНЫ
A2: на выполнение научно-исследовательской работы по теме: «ТЕМА»
A3: № п/п | B3: Предметные статьи расходов | C3: Всего по НИР сумма, руб. | D3: Этап 1 | E3: Этап 2 | F3: Этап 3 | G3: Этап 4 | H3: Этап 5 | I3: Этап 6
A4: 1 | B4: Прямые расходы, в том числе: | C4: =SUM(D4:I4) -> 0 | D4: =D5+D6+D7+D10+D11+D12+D13 -> 0 | E4: =E5+E6+E7+E10+E11+E12+E13 -> 0 | F4: =F5+F6+F7+F10+F11+F12+F13 -> 0 | G4: =G5+G6+G7+G10+G11+G12+G13 -> 0 | H4: =H5+H6+H7+H10+H11+H12+H13 -> 0 | I4: =I5+I6+I7+I10+I11+I12+I13 -> 0
A5: 1.1 | B5: материалы и комплектующие | C5: =SUM(D5:I5) -> 0 | D5: 0 | E5: 0 | F5: 0 | G5: 0 | H5: 0 | I5: 0
A6: 1.2 | B6: специальное оборудование | C6: =SUM(D6:I6) -> 0 | D6: 0 | E6: 0 | F6: 0 | G6: 0 | H6: 0 | I6: 0
A7: 1.3 | B7: расходы на оплату труда: | C7: =SUM(D7:I7) -> 0 | D7: =SUM(D8:D9) -> 0 | E7: =SUM(E8:E9) -> 0 | F7: =SUM(F8:F9) -> 0 | G7: =SUM(G8:G9) -> 0 | H7: =SUM(H8:H9) -> 0 | I7: =SUM(I8:I9) -> 0
A8: 1.3.1 | B8: основная заработная плата | C8: =SUM(D8:I8) -> 0 | D8: ='Расшифровка ФОТ'!I14 -> 0 | E8: ='Расшифровка ФОТ'!I22 -> 0 | F8: ='Расшифровка ФОТ'!I30 -> 0 | G8: ='Расшифровка ФОТ'!I38 -> 0 | H8: ='Расшифровка ФОТ'!I46 -> 0 | I8: ='Расшифровка ФОТ'!I54 -> 0
A9: 1.3.2 | B9: дополнительная заработная плата | C9: =SUM(D9:I9) -> 0 | D9: =D8*0.086866 -> 0 | E9: =E8*0.086866 -> 0 | F9: =F8*0.086866 -> 0 | G9: =G8*0.086866 -> 0 | H9: =H8*0.086866 -> 0 | I9: =I8*0.086866 -> 0
A10: 1.4 | B10: обязательные отчисления от оплаты труда | C10: =SUM(D10:I10) -> 0 | D10: =D7*0.302 -> 0 | E10: =E7*0.302 -> 0 | F10: =F7*0.302 -> 0 | G10: =G7*0.302 -> 0 | H10: =H7*0.302 -> 0 | I10: =I7*0.302 -> 0
A11: 1.5 | B11: амортизационные отчисления | C11: =SUM(D11:I11) -> 0 | D11: 0 | E11: 0 | F11: 0 | G11: 0 | H11: 0 | I11: 0
A12: 1.6 | B12: прочие прямые | C12: =SUM(D12:I12) -> 0 | D12: 0 | E12: 0 | F12: 0 | G12: 0 | H12: 0 | I12: 0
A13: 1.7 | B13: командировки и т.п. | C13: =SUM(D13:I13) -> 0 | D13: =Командировочные!L6 -> 0 | E13: =Командировочные!L7 -> 0 | F13: =Командировочные!L8 -> 0 | G13: =Командировочные!L9 -> 0 | H13: =Командировочные!L10 -> 0 | I13: =Командировочные!L11 -> 0
A14: 2 | B14: Накладные расходы (хх,хх% от п.1.3.1), в том числе: | C14: =SUM(D14:I14) -> 0 | D14: 0 | E14: 0 | F14: 0 | G14: 0 | H14: 0 | I14: 0
A15: 2.1 | B15: расходы на оплату труда административно-управленческого аппарата с отчислениями | C15: =SUM(D15:I15) -> 0 | D15: 0 | E15: 0 | F15: 0 | G15: 0 | H15: 0 | I15: 0
A16: 3 | B16: Всего расходов собственными силами | C16: =SUM(D16:I16) -> 0 | D16: =D4+D14 -> 0 | E16: =E4+E14 -> 0 | F16: =F4+F14 -> 0 | G16: =G4+G14 -> 0 | H16: =H4+H14 -> 0 | I16: =I4+I14 -> 0
A17: 4 | B17: Затраты на выполнение работ сторонними организациями | C17: =SUM(D17:I17) -> 0 | D17: 0 | E17: 0 | F17: 0 | G17: 0 | H17: 0 | I17: 0
A18: 5 | B18: Всего расходов | C18: =SUM(D18:I18) -> 0 | D18: =D16+D17 -> 0 | E18: =E16+E17 -> 0 | F18: =F16+F17 -> 0 | G18: =G16+G17 -> 0 | H18: =H16+H17 -> 0 | I18: =I16+I17 -> 0
A19: 6 | B19: Прибыль | C19: =SUM(D19:I19) -> 0 | D19: 0 | E19: 0 | F19: 0 | G19: 0 | H19: 0 | I19: 0
A20: 7 | B20: Цена договора без НДС | C20: =SUM(D20:I20) -> 0 | D20: =D18+D19 -> 0 | E20: =E18+E19 -> 0 | F20: =F18+F19 -> 0 | G20: =G18+G19 -> 0 | H20: =H18+H19 -> 0 | I20: =I18+I19 -> 0
A21: 8 | B21: НДС | C21: 0 | D21: 0 | E21: 0 | F21: 0 | G21: 0 | H21: 0 | I21: 0
A22: 9 | B22: Цена договора | C22: =C20+C21 -> 0 | D22: =D20+D21 -> 0 | E22: =E20+E21 -> 0 | F22: =F20+F21 -> 0 | G22: =G20+G21 -> 0 | H22: =H20+H21 -> 0 | I22: =I20+I21 -> 0
A25: Проректор по научной работе | G25: Главный бухгалтер
A27: ___________/ Фомин Ю.В./___ | G27: _________/Иванова Н.В./_________
A28: (подпись, ФИО, дата) | G28: (подпись, ФИО, дата)
A30: Руководитель договора | G30: Начальник ОФЭАУ НИОКР
A31: __________/Боровков А.И./ ______ | G31: _________/Васецкая Н.О./_________
A32: (подпись, ФИО, дата) | G32: (подпись, ФИО, дата)
A34: Ответственный исполнитель
A35: ________/Фамилия И.О./_______
A36: (подпись, ФИО, дата)

Sheet Материалы
A2: Расшифровка статьи «Материалы и комплектующие»
A3: =тема -> на выполнение научно-исследовательской работы по теме: «ТЕМА»
A4: № п/п | B4: Наименование материала/ комплектующих | C4: Модель/ производитель/ технические характеристики | D4: Срок поставки | E4: Ед. изм. | F4: Кол-во, шт. | G4: Цена за ед., руб. | H4: Сумма, руб.
A5: 1 | B5: 2 | C5: 3 | D5: 4 | E5: 5 | F5: 6 | G5: 7 | H5: 8
A6: - | B6: - | C6: - | D6: - | E6: - | F6: - | G6: - | H6: -
A7: - | B7: - | C7: - | D7: - | E7: - | F7: - | G7: - | H7: -
A8: - | B8: - | C8: - | D8: - | E8: - | F8: - | G8: - | H8: -
B9: ИТОГО: | C9: Х | D9: Х | E9: Х | G9: Х | H9: -
B11: Руководитель договора | F11: Начальник ОФЭАУ НИОКР
A12: __________/Боровков А.И./ ______ | F12: _________/Васецкая Н.О./_________
A13: (подпись, ФИО, дата) | F13: (подпись, ФИО, дата)
B15: Ответственный исполнитель
A16: ________/Фамилия И.О./_______
A17: (подпись, ФИО, дата)

Sheet Спец_обор
A1: Расшифровка статьи «Специальное оборудование»
A2: =тема -> на выполнение научно-исследовательской работы по теме: «ТЕМА»
A3: № п/п | B3: Наименование оборудования | C3: Производитель/ спецификация | D3: Срок поставки | E3: Кол-во, шт. | F3: Цена за ед., руб. | G3: Сумма, руб.
A4: 1 | B4: 2 | C4: 3 | D4: 4 | E4: 5 | F4: 6 | G4: 7
A5: - | B5: - | C5: - | D5: - | E5: - | F5: - | G5: -
A6: - | B6: - | C6: - | D6: - | E6: - | F6: - | G6: -
A7: - | B7: - | C7: - | D7: - | E7: - | F7: - | G7: -
B8: ИТОГО: | C8: Х | D8: Х | E8: Х | F8: Х | G8: -
A10: Руководитель договора | E10: Начальник ОФЭАУ НИОКР
A11: __________/Боровков А.И./ ______ | E11: _________/Васецкая Н.О./_________
A12: (подпись, ФИО, дата) | F12: (подпись, ФИО, дата)
A14: Ответственный исполнитель
A15: ________/Фамилия И.О./_______
A16: (подпись, ФИО, дата)

Sheet Расшифровка ФОТ
B2: Расшифровка статьи «Расходы на оплату труда» | J2: Справка НР и НТП от №
B3: =тема -> на выполнение научно-исследовательской работы по теме: «ТЕМА» | J3: Письмо Минэкономразвития от хх.10.202х № с индексами ИПЦ и ИРЗ
A4: № | B4: № этапа | C4: Тип работ | D4: Должность | E4: Кол-во человек | F4: Тудоемкость на 1 чел., мес ЛИБО час | G4: Кол-во чел/мес. | H4: Сумма месячной з/пл., руб. | I4: Итого ФОТ, руб. | J4: Среднемесячное количество рабочих часов в 2026 г.- 164,25, в 2027 г. -165,58
A5: п/п | I5: (гр6*гр7)
A6: 1 | B6: 2 | C6: 3 | D6: 4 | E6: 5 | F6: скрыть | G6: 6 | H6: 7 | I6: 8 | J6: НАЧАЛО ЭТАПА | K6: ОКОНЧАНИЕ ЭТАПА
A7: 1 | B7: Этап 1 | D7: Руководитель работ | E7: 0 | F7: 0 | G7: =E7*F7 -> 0 | H7: 0 | I7: =G7*H7 -> 0 | J7: хх.хх.хххх | K7: хх.хх.хххх
A8: 2 | D8: Ведущий инженер | E8: 0 | F8: 0 | G8: =E8*F8 -> 0 | H8: 0 | I8: =G8*H8 -> 0 | J8: хх.хх.хххх | K8: хх.хх.хххх
A9: 3 | D9: Научный сотрудник | E9: 0 | F9: 0 | G9: =E9*F9 -> 0 | H9: 0 | I9: =G9*H9 -> 0 | J9: хх.хх.хххх | K9: хх.хх.хххх
A10: 4 | D10: Младший научный сотрудник | E10: 0 | F10: 0 | G10: =E10*F10 -> 0 | H10: 0 | I10: =G10*H10 -> 0 | J10: хх.хх.хххх | K10: хх.хх.хххх
A11: 5 | D11: Инженер | E11: 0 | F11: 0 | G11: =E11*F11 -> 0 | H11: 0 | I11: =G11*H11 -> 0 | J11: хх.хх.хххх | K11: хх.хх.хххх
A12: 6 | D12: Инженер I-категории | E12: 0 | F12: 0 | G12: =E12*F12 -> 0 | H12: 0 | I12: =G12*H12 -> 0 | J12: хх.хх.хххх | K12: хх.хх.хххх
A13: 7 | D13: Специалист | E13: 0 | F13: 0 | G13: =E13*F13 -> 0 | H13: 0 | I13: =G13*H13 -> 0 | J13: хх.хх.хххх | K13: хх.хх.хххх
B14: Итого по Этапу 1 | E14: =SUM(E7:E13) -> 0 | F14: =SUM(F7:F13) -> 0 | G14: =SUM(G7:G13) -> 0 | H14: =I14/G14 -> #DIV/0! | I14: =SUM(I7:I13) -> 0
A15: 1 | B15: Этап 2 | D15: Руководитель работ | E15: 0 | F15: 0 | G15: =E15*F15 -> 0 | H15: 0 | I15: =G15*H15 -> 0 | J15: хх.хх.хххх | K15: хх.хх.хххх
A16: 2 | D16: Ведущий инженер | E16: 0 | F16: 0 | G16: =E16*F16 -> 0 | H16: 0 | I16: =G16*H16 -> 0 | J16: хх.хх.хххх | K16: хх.хх.хххх
A17: 3 | D17: Научный сотрудник | E17: 0 | F17: 0 | G17: =E17*F17 -> 0 | H17: 0 | I17: =G17*H17 -> 0 | J17: хх.хх.хххх | K17: хх.хх.хххх
A18: 4 | D18: Младший научный сотрудник | E18: 0 | F18: 0 | G18: =E18*F18 -> 0 | H18: 0 | I18: =G18*H18 -> 0 | J18: хх.хх.хххх | K18: хх.хх.хххх
A19: 5 | D19: Инженер | E19: 0 | F19: 0 | G19: =E19*F19 -> 0 | H19: 0 | I19: =G19*H19 -> 0 | J19: хх.хх.хххх | K19: хх.хх.хххх
A20: 6 | D20: Инженер I-категории | E20: 0 | F20: 0 | G20: =E20*F20 -> 0 | H20: 0 | I20: =G20*H20 -> 0 | J20: хх.хх.хххх | K20: хх.хх.хххх
A21: 7 | D21: Специалист | E21: 0 | F21: 0 | G21: =E21*F21 -> 0 | H21: 0 | I21: =G21*H21 -> 0 | J21: хх.хх.хххх | K21: хх.хх.хххх
B22: Итого по Этапу 2 | E22: =SUM(E15:E21) -> 0 | F22: =SUM(F15:F21) -> 0 | G22: =SUM(G15:G21) -> 0 | H22: =I22/G22 -> #DIV/0! | I22: =SUM(I15:I21) -> 0
A23: 1 | B23: Этап 3 | D23: Руководитель работ | E23: 0 | F23: 0 | G23: =E23*F23 -> 0 | H23: 0 | I23: =G23*H23 -> 0 | J23: хх.хх.хххх | K23: хх.хх.хххх
A24: 2 | D24: Ведущий инженер | E24: 0 | F24: 0 | G24: =E24*F24 -> 0 | H24: 0 | I24: =G24*H24 -> 0 | J24: хх.хх.хххх | K24: хх.хх.хххх
A25: 3 | D25: Научный сотрудник | E25: 0 | F25: 0 | G25: =E25*F25 -> 0 | H25: 0 | I25: =G25*H25 -> 0 | J25: хх.хх.хххх | K25: хх.хх.хххх
A26: 4 | D26: Младший научный сотрудник | E26: 0 | F26: 0 | G26: =E26*F26 -> 0 | H26: 0 | I26: =G26*H26 -> 0 | J26: хх.хх.хххх | K26: хх.хх.хххх
A27: 5 | D27: Инженер | E27: 0 | F27: 0 | G27: =E27*F27 -> 0 | H27: 0 | I27: =G27*H27 -> 0 | J27: хх.хх.хххх | K27: хх.хх.хххх
A28: 6 | D28: Инженер I-категории | E28: 0 | F28: 0 | G28: =E28*F28 -> 0 | H28: 0 | I28: =G28*H28 -> 0 | J28: хх.хх.хххх | K28: хх.хх.хххх
A29: 7 | D29: Специалист | E29: 0 | F29: 0 | G29: =E29*F29 -> 0 | H29: 0 | I29: =G29*H29 -> 0 | J29: хх.хх.хххх | K29: хх.хх.хххх
B30: Итого по Этапу 3 | E30: =SUM(E23:E29) -> 0 | F30: =SUM(F23:F29) -> 0 | G30: =SUM(G23:G29) -> 0 | H30: =I30/G30 -> #DIV/0! | I30: =SUM(I23:I29) -> 0
A31: 1 | B31: Этап 4 | D31: Руководитель работ | E31: 0 | F31: 0 | G31: =E31*F31 -> 0 | H31: 0 | I31: =G31*H31 -> 0 | J31: хх.хх.хххх | K31: хх.хх.хххх
A32: 2 | D32: Ведущий инженер | E32: 0 | F32: 0 | G32: =E32*F32 -> 0 | H32: 0 | I32: =G32*H32 -> 0 | J32: хх.хх.хххх | K32: хх.хх.хххх
A33: 3 | D33: Научный сотрудник | E33: 0 | F33: 0 | G33: =E33*F33 -> 0 | H33: 0 | I33: =G33*H33 -> 0 | J33: хх.хх.хххх | K33: хх.хх.хххх
A34: 4 | D34: Младший научный сотрудник | E34: 0 | F34: 0 | G34: =E34*F34 -> 0 | H34: 0 | I34: =G34*H34 -> 0 | J34: хх.хх.хххх | K34: хх.хх.хххх
A35: 5 | D35: Инженер | E35: 0 | F35: 0 | G35: =E35*F35 -> 0 | H35: 0 | I35: =G35*H35 -> 0 | J35: хх.хх.хххх | K35: хх.хх.хххх
A36: 6 | D36: Инженер I-категории | E36: 0 | F36: 0 | G36: =E36*F36 -> 0 | H36: 0 | I36: =G36*H36 -> 0 | J36: хх.хх.хххх | K36: хх.хх.хххх
A37: 7 | D37: Специалист | E37: 0 | F37: 0 | G37: =E37*F37 -> 0 | H37: 0 | I37: =G37*H37 -> 0 | J37: хх.хх.хххх | K37: хх.хх.хххх
B38: Итого по Этапу 4 | E38: =SUM(E31:E37) -> 0 | F38: =SUM(F31:F37) -> 0 | G38: =SUM(G31:G37) -> 0 | H38: =I38/G38 -> #DIV/0! | I38: =SUM(I31:I37) -> 0
A39: 1 | B39: Этап 5 | D39: Руководитель работ | E39: 0 | F39: 0 | G39: =E39*F39 -> 0 | H39: 0 | I39: =G39*H39 -> 0 | J39: хх.хх.хххх | K39: хх.хх.хххх
A40: 2 | D40: Ведущий инженер | E40: 0 | F40: 0 | G40: =E40*F40 -> 0 | H40: 0 | I40: =G40*H40 -> 0 | J40: хх.хх.хххх | K40: хх.хх.хххх
A41: 3 | D41: Научный сотрудник | E41: 0 | F41: 0 | G41: =E41*F41 -> 0 | H41: 0 | I41: =G41*H41 -> 0 | J41: хх.хх.хххх | K41: хх.хх.хххх
...

Sheet Амортизация
A1: Расшифровка статьи «Амортизационные отчисления»
A2: =тема -> на выполнение научно-исследовательской работы по теме: «ТЕМА»
A3: № этапа | B3: Наименование оборудования | C3: Применение для выполнения СЧ НИР по теме | D3: Балансовая стоимость, руб. | E3: Амортизация в месяц, руб. | F3: Число месяцев исполь-зования | G3: Итого амортизация, руб. (гр.5*гр.6)
A4: 1 | B4: 2 | C4: 3 | D4: 4 | E4: 5 | F4: 6 | G4: 7
A5: - | B5: - | C5: - | D5: - | E5: - | F5: - | G5: -
A6: - | B6: - | C6: - | D6: - | E6: - | F6: - | G6: -
A7: - | B7: - | C7: - | D7: - | E7: - | F7: - | G7: -
B8: ИТОГО: | C8: Х | D8: Х | E8: Х | F8: Х | G8: -
A11: Руководитель договора | E11: Начальник ОФЭАУ НИОКР
A12: __________/Боровков А.И./ ______ | E12: _________/Васецкая Н.О./_________
A13: (подпись, ФИО, дата) | E13: (подпись, ФИО, дата)
A15: Ответственный исполнитель
A16: ________/Фамилия И.О./_______
A17: (подпись, ФИО, дата)

Sheet Прочие прямые
A1: Расшифровка статьи «Прочие прямые расходы»
A2: =тема -> на выполнение научно-исследовательской работы по теме: «ТЕМА»
A3: № этапа | B3: Наименование (содержание) расходов | C3: Сумма, руб. | D3: Обоснование расходов
A4: 1 | B4: 2 | C4: 3 | D4: 4
A5: - | B5: - | C5: - | D5: -
B6: Итого по этапу 1 | C6: - | D6: -
A7: - | B7: - | C7: - | D7: -
B8: Итого по этапу … | C8: - | D8: -
A9: - | B9: - | C9: - | D9: -
B10: Итого по этапу … | C10: - | D10: -
A11: ИТОГО по теме | C11: - | D11: Х
A13: Руководитель договора | D13: Начальник ОФЭАУ НИОКР
A14: __________/Боровков А.И./ ______ | D14: _________/Васецкая Н.О./_________
A15: (подпись, ФИО, дата) | D15: (подпись, ФИО, дата)
A16: Ответственный исполнитель
A17: ________/Фамилия И.О./_______
A18: (подпись, ФИО, дата)

Sheet Командировочные
B1: Расшифровка статьи «Командировки»
B2: =тема -> на выполнение научно-исследовательской работы по теме: «ТЕМА»
A3: № п/п | B3: Наименование города, страны, куда командируются работники | C3: Количество человек | D3: Количество командировок | E3: Кол-во суток нахождения в командировке | F3: Норма оплаты, руб. | I3: Сумма, руб. | L3: ВСЕГО, руб. | M3: № этапа
F4: Суточных | G4: Квартирных | H4: За проезд | I4: Суточных | J4: Квартирных | K4: За проезд
A5: 1 | B5: 2 | C5: 3 | D5: 4 | E5: 5 | F5: 6 | G5: 7 | H5: 8 | I5: 9 | J5: 10 | K5: 11 | L5: 12 | M5: 13
A6: 1 | C6: 0 | D6: 0 | E6: 0 | F6: 700 | G6: 0 | H6: 0 | I6: =F6*E6*C6 -> 0 | J6: =G6*C6 -> 0 | K6: =H6*C6 -> 0 | L6: =SUM(I6:K6) -> 0 | M6: 1
A7: 2 | C7: 0 | D7: 0 | E7: 2 | F7: 700 | G7: 0 | H7: 0 | I7: =F7*E7*D7*C7 -> 0 | J7: =G7*C7 -> 0 | K7: =H7*C7 -> 0 | L7: =SUM(I7:K7) -> 0 | M7: 2
A8: 3 | C8: 0 | D8: 0 | E8: 2 | F8: 700 | G8: 0 | H8: 0 | I8: =F8*E8*D8*C8 -> 0 | J8: =G8*C8 -> 0 | K8: =H8*C8 -> 0 | L8: =SUM(I8:K8) -> 0 | M8: 3
A9: 4 | C9: 0 | D9: 0 | E9: 2 | F9: 700 | G9: 0 | H9: 0 | I9: =F9*E9*D9*C9 -> 0 | J9: =G9*C9 -> 0 | K9: =H9*C9 -> 0 | L9: =SUM(I9:K9) -> 0 | M9: 4
A10: 5 | C10: 0 | D10: 0 | E10: 2 | F10: 700 | G10: 0 | H10: 0 | I10: =F10*E10*D10*C10 -> 0 | J10: =G10*C10 -> 0 | K10: =H10*C10 -> 0 | L10: =SUM(I10:K10) -> 0 | M10: 5
A11: 6 | C11: 0 | D11: 0 | E11: 2 | F11: 700 | G11: 0 | H11: 0 | I11: =F11*E11*D11*C11 -> 0 | J11: =G11*C11 -> 0 | K11: =H11*C11 -> 0 | L11: =SUM(I11:K11) -> 0 | M11: 6
B12: ИТОГО: | C12: Х | D12: Х | E12: Х | F12: Х | G12: Х | H12: Х | I12: Х | J12: Х | K12: Х | L12: =SUM(L6:L11) -> 0 | M12: Х
A15: Руководитель договора | H15: Начальник ОФЭАУ НИОКР
A16: __________/Боровков А.И./ ______ | H16: _________/Васецкая Н.О./_________
A17: (подпись, ФИО, дата) | H17: (подпись, ФИО, дата)
A18: Ответственный исполнитель
A19: ________/Фамилия И.О./_______
A20: (подпись, ФИО, дата)

Sheet Накладные
A1: СПРАВКА
A2: о размере накладных расходов
A3: =тема -> на выполнение научно-исследовательской работы по теме: «ТЕМА»
A4: Накладные расходы по организации в целом, тыс. руб./ % к основной заработной плате исполнителей | D4: Принятый % накладных расходов по заключаемому Госконтракту (Дополнительному соглашению) к общему объему поступлений средств/ основной заработной плате исполнителей | E4: Плановая сумма накладных расходов по заключаемому Госконтракту (Дополнительному соглашению), тыс. руб.
A5: 2025 год (предыдущий год) | C5: Планируемый
A6: План | B6: Факт | C6: 2024г.
A7: 1 | B7: 2 | C7: 3 | D7: 4 | E7: 5
A8: / 0,0% (0%) | B8: / 0,0% (0%) | C8: / 0,0% (0%) | D8: / 0,0% (0%) | E8: 0
A10: Главный бухгалтер | D10: Начальник ОФЭАУ НИОКР
A11: ___________/Иванова Н.В./_____ | D11: _________/Васецкая Н.О./_________
A12: (подпись, ФИО, дата) | D12: (подпись, ФИО, дата)

Sheet Стор_орг
A1: Расшифровка статьи «Затраты на выполнение работ сторонними организациями»
A2: =тема -> на выполнение научно-исследовательской работы по теме: «ТЕМА»
A3: № этапа | B3: Наименование организаций соисполнителей и контрагентов | C3: Наименование выполняемых работ (предмет договора) | D3: Сроки исполнения | E3: Цена договора, руб. | F3: Основание | G3: № этапа
A4: 1 | B4: 2 | C4: 3 | D4: 4 | E4: 5 | F4: 6 | G4: 7
A5: - | B5: - | C5: - | D5: - | E5: - | F5: - | G5: -
A6: - | B6: - | C6: - | D6: - | E6: - | F6: - | G6: -
A7: - | B7: - | C7: - | D7: - | E7: - | F7: - | G7: -
B8: ИТОГО: | C8: Х | D8: Х | E8: - | F8: Х | G8: Х
A11: Руководитель договора | E11: Начальник ОФЭАУ НИОКР
A12: __________/Боровков А.И./ ______ | E12: _________/Васецкая Н.О./_________
A13: (подпись, ФИО, дата) | F13: (подпись, ФИО, дата)
A15: Ответственный исполнитель
A16: ________/Фамилия И.О./_______
A17: (подпись, ФИО, дата)
